Workbook

Sheet Cover
D3: Commercial Performance Review - Due Dilligence Case Study
D5: Kenneth Christopher | April 2026
B10: Data Source | D10: Global Superstore Transactional Dataset 2011-2014
B12: Key Investment Question | D12: Should an investor acquire this business given its revenue growth trajectory, margin profle, and operational risks?
B18: Investment View | D18: Conditional Buy | I18: Subject to: Office Supplies cost structure review, Tables pricing rationalisation
B20: Analysis | D20: Strong revenue growth (~24% CAGR) with stable margins of 11-12%
D21: Furniture is the key underperformer, 32.5% of revenue but only 19.4% of profit at 7% margins
D22: Clear value creation opportunity through Office Supplies margin recovery and Tables Pricing Discipline

Sheet Inputs
B1: Commercial Performance Revenue - Due Dilligence Case Study | Inputs Sheet
B3: Drivers
B5: All figures in USD unless stated | I5: 2015F | J5: 2016F | K5: 2017F | L5: 2018F
B7: Driver Switch | D7: 3
B10: Revenue Growth % | I10: =I90 -> 0.08 | J10: =J90 -> 0.08 | K10: =K90 -> 0.08 | L10: =L90 -> 0.08
B13: OC Margin % | I13: =I96 -> 0.122 | J13: =J96 -> 0.122 | K13: =K96 -> 0.122 | L13: =L96 -> 0.122
B16: Fixed Costs % | I16: =I102 -> 0.02 | J16: =J102 -> 0.02 | K16: =K102 -> 0.02 | L16: =L102 -> 0.02
B19: Tax Rate % | I19: =I108 -> 0.25 | J19: =J108 -> 0.25 | K19: =K108 -> 0.25 | L19: =L108 -> 0.25
B22: Historical Operating Performance
B24: All figures in USD unless stated | I24: 2011A | J24: 2012A | K24: 2013A | L24: 2014A
B26: Revenue | I26: ='02_analysis_time_series'!B2 -> 2259450.9 | J26: ='02_analysis_time_series'!B3 -> 2677438.7 | K26: ='02_analysis_time_series'!B4 -> 3405746.5 | L26: ='02_analysis_time_series'!B5 -> 4299865.9
B27: Cost of Sales | I27: =(I26-I28)*-1 -> -2010510.1 | J27: =(J26-J28)*-1 -> -2370023.4 | K27: =(K26-K28)*-1 -> -2998811.2 | L27: =(L26-L28)*-1 -> -3795699.9
B28: Operating Contribution | I28: ='02_analysis_time_series'!C2 -> 248940.81 | J28: ='02_analysis_time_series'!C3 -> 307415.28 | K28: ='02_analysis_time_series'!C4 -> 406935.23 | L28: ='02_analysis_time_series'!C5 -> 504165.97
B30: OC Margin % | I30: ='02_analysis_time_series'!D2/100 -> 0.1102 | J30: ='02_analysis_time_series'!D3/100 -> 0.1148 | K30: ='02_analysis_time_series'!D4/100 -> 0.1195 | L30: ='02_analysis_time_series'!D5/100 -> 0.1173
B31: YoY Revenue Growth % | I31: ='02_analysis_time_series'!F2/100 -> 0 | J31: ='02_analysis_time_series'!F3/100 -> 0.18 | K31: ='02_analysis_time_series'!F4/100 -> 0.27 | L31: ='02_analysis_time_series'!F5/100 -> 0.26
B32: YoY Profit Growth % | I32: ='02_analysis_time_series'!G2/100 -> 0 | J32: ='02_analysis_time_series'!G3/100 -> 0.23 | K32: ='02_analysis_time_series'!G4/100 -> 0.32 | L32: ='02_analysis_time_series'!G5/100 -> 0.24
B34: Operating Contribution reflects revenue less direct product costs as recorded in transactional data. This figure is inclusive of variable operating costs and is not directly comparable to a standard gross profit line in an audited P&L.
B38: Analytical Insights (Data-driven)
B40: Category Performance Summary
B42: All figures in USD unless stated | H42: Revenue | I42: Revenue Share % | J42: OC Margin % | K42: Profit | L42: Profit Contribution %
B44: Technology | H44: ='03_cateogry_analysis'!B2 -> 4744557.5 | I44: =H44/(SUM($H$44:$H$46)) -> 0.37528628 | J44: ='03_cateogry_analysis'!D2/100 -> 0.14 | K44: ='03_cateogry_analysis'!C2 -> 663778.73 | L44: =K44/SUM($K$44:$K$46) -> 0.45233257
B45: Office Supplies | H45: ='03_cateogry_analysis'!B3 -> 4110874.2 | I45: =H45/(SUM($H$44:$H$46)) -> 0.32516303 | J45: ='03_cateogry_analysis'!D3/100 -> 0.07 | K45: ='03_cateogry_analysis'!C3 -> 285204.72 | L45: =K45/SUM($K$44:$K$46) -> 0.194353
B46: Furniture | H46: ='03_cateogry_analysis'!B4 -> 3787070.2 | I46: =H46/(SUM($H$44:$H$46)) -> 0.29955069 | J46: ='03_cateogry_analysis'!D4/100 -> 0.14 | K46: ='03_cateogry_analysis'!C4 -> 518473.83 | L46: =K46/SUM($K$44:$K$46) -> 0.35331443
B49: Office Supplies is the weakest category, contributing only 19.4% of profit despite 32.5% of revenue, driven by a materially lower 7% margin versus 14% for Technology and Furniture.
B54: Sub-Category Risk Flags
B56: All figures in USD unless stated | G56: OC Margin % | H56: Avg Selling Price | I56: Avg Cost | J56: Avg Profit | K56: Risk Discount % | L56: Classification
B58: Tables | G58: ='04_product_subcategory_analysis'!E18/100 -> -0.08 | H58: ='09_unit_economics_diagnostic'!G2 -> 245.55 | I58: ='09_unit_economics_diagnostic'!H2 -> 266.34 | J58: ='09_unit_economics_diagnostic'!I2 -> -20.79 | K58: ='09_unit_economics_diagnostic'!F2 -> 0.29 | L58: ='09_unit_economics_diagnostic'!J2 -> Pricing Risk-Excessive Discounting
B61: Tables is the only loss-making sub-category, with a -8% margin driven by 29% discounting, indicating a pricing-led profitability issue rather than structural cost inefficiency.
B65: Tables classification (Cost Risk vs Pricing Risk) determined by unit economics query. If avg discount > 20% alongside negative margin → Pricing Risk. If avg discount < 10 alongside negative margin → Structural Cost Risk.
B69: Discount Analysis Summary
B71: All figures in USD unless stated
H72: %
B73: Company Average Discount Rate | H73: {=_08_discount[Discount]} -> 0.14290755
B74: Furniture Average Discount Rate | H74: 0.1875
B75: Technology Average Discount Rate | H75: 0.14384615
B76: Office Supplies Average Discount Rate | H76: 0.13733333
B79: Discounting is not the primary driver of category-level margin differences. While Tables exhibits excessive discounting (29% vs 14.3% average), Office Supplies underperformance appears driven by cost structure rather than pricing
B83: Data Driven Assumptions
B85: Forward Scenario Assumptions
B87: All figures in USD unless stated | I87: 2015F | J87: 2016F | K87: 2017F | L87: 2018F
...

Sheet P&L
B1: Commercial Performance Revenue - Due Dilligence Case Study | P&L
B3: Historical Operating Performance
B5: All figures in USD unless stated | K5: 2011A | L5: 2012A | M5: 2013A | N5: 2014A
B7: Revenue | K7: =Inputs!I26 -> 2259450.9 | L7: =Inputs!J26 -> 2677438.7 | M7: =Inputs!K26 -> 3405746.5 | N7: =Inputs!L26 -> 4299865.9
B8: YoY Growth % | K8: =Inputs!I31 -> 0 | L8: =Inputs!J31 -> 0.18 | M8: =Inputs!K31 -> 0.27 | N8: =Inputs!L31 -> 0.26
B10: Cost of Sales | K10: =Inputs!I27 -> -2010510.1 | L10: =Inputs!J27 -> -2370023.4 | M10: =Inputs!K27 -> -2998811.2 | N10: =Inputs!L27 -> -3795699.9
B11: Cost of Sales as % of Revenue | K11: =K10/K7*-1 -> 0.88982243 | L11: =L10/L7*-1 -> 0.88518307 | M11: =M10/M7*-1 -> 0.88051511 | N11: =N10/N7*-1 -> 0.88274844
B13: Operating Contribution | K13: =Inputs!I28 -> 248940.81 | L13: =Inputs!J28 -> 307415.28 | M13: =Inputs!K28 -> 406935.23 | N13: =Inputs!L28 -> 504165.97
B14: OC Margin % | K14: =Inputs!I30 -> 0.1102 | L14: =Inputs!J30 -> 0.1148 | M14: =Inputs!K30 -> 0.1195 | N14: =Inputs!L30 -> 0.1173
B15: YoY OC Growth | K15: =Inputs!I32 -> 0 | L15: =Inputs!J32 -> 0.23 | M15: =Inputs!K32 -> 0.32 | N15: =Inputs!L32 -> 0.24
B17: Operating Contribution = Revenue less direct product costs from transactional data. Inclusive of variable operating costs. Not directly comparable to audited gross profit.Full cost decomposition requires audited financial statements
B20: Illustrative Forward Scenario
B22: All figures in USD unless stated | J22: 2014A | L22: 2016F | M22: 2017F | N22: 2018F
B24: Model Driver Set to | E24: =IF(Inputs!D7=1,"Downside",IF(Inputs!D7=2,"Base","Upside")) -> Upside
B26: Tax Rate | D26: =Inputs!I19 -> 0.25
B28: Revenue Growth | G28: 0 | H28: =(H34-G34)/G34 -> 0.1849953 | I28: =(I34-H34)/H34 -> 0.2720166 | J28: =(J34-I34)/I34 -> 0.26253259 | K28: =Inputs!I10 -> 0.08 | L28: =Inputs!J10 -> 0.08 | M28: =Inputs!K10 -> 0.08 | N28: =Inputs!L10 -> 0.08
B30: OC Margin % | G30: =G36/G34 -> 0.11017757 | H30: =H36/H34 -> 0.11481693 | I30: =I36/I34 -> 0.11948489 | J30: =J36/J34 -> 0.11725156 | K30: =Inputs!I13 -> 0.122 | L30: =Inputs!J13 -> 0.122 | M30: =Inputs!K13 -> 0.122 | N30: =Inputs!L13 -> 0.122
B32: Fixed Cost % | G32: 0 | H32: 0 | I32: 0 | J32: 0 | K32: =Inputs!I16 -> 0.02 | L32: =Inputs!J16 -> 0.02 | M32: =Inputs!K16 -> 0.02 | N32: =Inputs!L16 -> 0.02
B34: Revenue | G34: ='P&L'!K7 -> 2259450.9 | H34: ='P&L'!L7 -> 2677438.7 | I34: ='P&L'!M7 -> 3405746.5 | J34: ='P&L'!N7 -> 4299865.9 | K34: =J34*(1+K28) -> 4643855.1 | L34: =K34*(1+L28) -> 5015363.6 | M34: =L34*(1+M28) -> 5416592.6 | N34: =M34*(1+N28) -> 5849920
B35: Cost of Sales | G35: =K10 -> -2010510.1 | H35: =L10 -> -2370023.4 | I35: =M10 -> -2998811.2 | J35: =N10 -> -3795699.9 | K35: =(K34-K36)*-1 -> -4077304.8 | L35: =(L34-L36)*-1 -> -4403489.2 | M35: =(M34-M36)*-1 -> -4755768.3 | N35: =(N34-N36)*-1 -> -5136229.8
B36: Operating Contribution | G36: =K13 -> 248940.81 | H36: =L13 -> 307415.28 | I36: =M13 -> 406935.23 | J36: =N13 -> 504165.97 | K36: =K34*K30 -> 566550.33 | L36: =L34*L30 -> 611874.35 | M36: =M34*M30 -> 660824.3 | N36: =N34*N30 -> 713690.25
B38: Fixed Overhead | G38: 0 | H38: 0 | I38: 0 | J38: 0 | K38: =K34*K32*-1 -> -92877.103 | L38: =L34*L32*-1 -> -100307.27 | M38: =M34*M32*-1 -> -108331.85 | N38: =N34*N32*-1 -> -116998.4
B39: Illustrative EBIT | G39: =G36+G38 -> 248940.81 | H39: =H36+H38 -> 307415.28 | I39: =I36+I38 -> 406935.23 | J39: =J36+J38 -> 504165.97 | K39: =K36+K38 -> 473673.22 | L39: =L36+L38 -> 511567.08 | M39: =M36+M38 -> 552492.45 | N39: =N36+N38 -> 596691.84
B41: EBIT Margin % | G41: =G39/G34 -> 0.11017757 | H41: =H39/H34 -> 0.11481693 | I41: =I39/I34 -> 0.11948489 | J41: =J39/J34 -> 0.11725156 | K41: =K39/K34 -> 0.102 | L41: =L39/L34 -> 0.102 | M41: =M39/M34 -> 0.102 | N41: =N39/N34 -> 0.102
B43: Tax | G43: =G39*$D$26*-1 -> -62235.202 | H43: =H39*$D$26*-1 -> -76853.82 | I43: =I39*$D$26*-1 -> -101733.81 | J43: =J39*$D$26*-1 -> -126041.49 | K43: =K39*$D$26*-1 -> -118418.31 | L43: =L39*$D$26*-1 -> -127891.77 | M43: =M39*$D$26*-1 -> -138123.11 | N43: =N39*$D$26*-1 -> -149172.96
B45: Illustrative Net Profit | G45: =G39+G43 -> 186705.61 | H45: =H39+H43 -> 230561.46 | I45: =I39+I43 -> 305201.42 | J45: =J39+J43 -> 378124.48 | K45: =K39+K43 -> 355254.92 | L45: =L39+L43 -> 383675.31 | M45: =M39+M43 -> 414369.34 | N45: =N39+N43 -> 447518.88

Sheet Dashboard
B1: Commercial Performance Revenue - Due Dilligence Case Study | P&L
B3: Global Superstore Dataset 2011-2014 | X3: Data: Revenue and Margin Trend
AA5: 2011A | AB5: 2012A | AC5: 2013A | AD5: 2014A
X6: Furniture | AA6: ='10_analysis_time_series_categor'!C2 -> 756192.38 | AB6: ='10_analysis_time_series_categor'!C5 -> 858902.56 | AC6: ='10_analysis_time_series_categor'!C8 -> 1117723.6 | AD6: ='10_analysis_time_series_categor'!C11 -> 1378055.7
X7: Office Supplies | AA7: ='10_analysis_time_series_categor'!C3 -> 675606.45 | AB7: ='10_analysis_time_series_categor'!C6 -> 795094.63 | AC7: ='10_analysis_time_series_categor'!C9 -> 1010717.6 | AD7: ='10_analysis_time_series_categor'!C12 -> 1305651.5
X8: Technology | AA8: ='10_analysis_time_series_categor'!C4 -> 827652.06 | AB8: ='10_analysis_time_series_categor'!C7 -> 1023441.5 | AC8: ='10_analysis_time_series_categor'!C10 -> 1277305.2 | AD8: ='10_analysis_time_series_categor'!C13 -> 1616158.7
X9: Total Revenue | AA9: =SUM(AA6:AA8) -> 2259450.9 | AB9: =SUM(AB6:AB8) -> 2677438.7 | AC9: =SUM(AC6:AC8) -> 3405746.4 | AD9: =SUM(AD6:AD8) -> 4299865.9
X11: OC Margin % | AA11: ='P&L'!K14 -> 0.1102 | AB11: ='P&L'!L14 -> 0.1148 | AC11: ='P&L'!M14 -> 0.1195 | AD11: ='P&L'!N14 -> 0.1173
X13: Profit Contribution vs Revenue Share
AA15: Revenue Share % | AB15: Profit Contribution %
X16: Furniture | AA16: ='03_cateogry_analysis'!E3/100 -> 0.3252 | AB16: ='07_profit_analysis'!F4/100 -> 0.1944
X17: Office Supplies | AA17: ='03_cateogry_analysis'!E4/100 -> 0.2996 | AB17: ='07_profit_analysis'!F3/100 -> 0.3533
X18: Technology | AA18: ='03_cateogry_analysis'!E2/100 -> 0.3753 | AB18: ='07_profit_analysis'!F2/100 -> 0.4523
B20: Revenue Growing at 24% CAGR - Margin Stable at 12% | M20: Furniture Significantly Under-Contributing to Profit | X20: Sub-Category Margin Ranked
X22: Category | Y22: Subcategory | Z22: Axis Title | AA22: Margin % | AB22: Zero Line
X23: ='04_product_subcategory_analysis'!B18 -> Furniture | Y23: ='04_product_subcategory_analysis'!A18 -> Tables | Z23: =Y23 & " (" & X23 & ")" -> Tables (Furniture) | AA23: ='04_product_subcategory_analysis'!E18/100 -> -0.08 | AB23: =0 -> 0
X24: ='04_product_subcategory_analysis'!B17 -> Technology | Y24: ='04_product_subcategory_analysis'!A17 -> Machines | Z24: =Y24 & " (" & X24 & ")" -> Machines (Technology) | AA24: ='04_product_subcategory_analysis'!E17/100 -> 0.08 | AB24: =0 -> 0
X25: ='04_product_subcategory_analysis'!B15 -> Office Supplies | Y25: ='04_product_subcategory_analysis'!A15 -> Supplies | Z25: =Y25 & " (" & X25 & ")" -> Supplies (Office Supplies) | AA25: ='04_product_subcategory_analysis'!E15/100 -> 0.09 | AB25: =0 -> 0
X26: ='04_product_subcategory_analysis'!B16 -> Furniture | Y26: ='04_product_subcategory_analysis'!A16 -> Chairs | Z26: =Y26 & " (" & X26 & ")" -> Chairs (Furniture) | AA26: ='04_product_subcategory_analysis'!E16/100 -> 0.09 | AB26: =0 -> 0
X27: ='04_product_subcategory_analysis'!B14 -> Office Supplies | Y27: ='04_product_subcategory_analysis'!A14 -> Storage | Z27: =Y27 & " (" & X27 & ")" -> Storage (Office Supplies) | AA27: ='04_product_subcategory_analysis'!E14/100 -> 0.1 | AB27: =0 -> 0
X28: ='04_product_subcategory_analysis'!B13 -> Furniture | Y28: ='04_product_subcategory_analysis'!A13 -> Bookcases | Z28: =Y28 & " (" & X28 & ")" -> Bookcases (Furniture) | AA28: ='04_product_subcategory_analysis'!E13/100 -> 0.11 | AB28: =0 -> 0
X29: ='04_product_subcategory_analysis'!B12 -> Furniture | Y29: ='04_product_subcategory_analysis'!A12 -> Furnishings | Z29: =Y29 & " (" & X29 & ")" -> Furnishings (Furniture) | AA29: ='04_product_subcategory_analysis'!E12/100 -> 0.12 | AB29: =0 -> 0
X30: ='04_product_subcategory_analysis'!B11 -> Technology | Y30: ='04_product_subcategory_analysis'!A11 -> Phones | Z30: =Y30 & " (" & X30 & ")" -> Phones (Technology) | AA30: ='04_product_subcategory_analysis'!E11/100 -> 0.13 | AB30: =0 -> 0
X31: ='04_product_subcategory_analysis'!B9 -> Office Supplies | Y31: ='04_product_subcategory_analysis'!A9 -> Fasteners | Z31: =Y31 & " (" & X31 & ")" -> Fasteners (Office Supplies) | AA31: ='04_product_subcategory_analysis'!E9/100 -> 0.14 | AB31: =0 -> 0
X32: ='04_product_subcategory_analysis'!B10 -> Office Supplies | Y32: ='04_product_subcategory_analysis'!A10 -> Appliances | Z32: =Y32 & " (" & X32 & ")" -> Appliances (Office Supplies) | AA32: ='04_product_subcategory_analysis'!E10/100 -> 0.14 | AB32: =0 -> 0
X33: ='04_product_subcategory_analysis'!B7 -> Office Supplies | Y33: ='04_product_subcategory_analysis'!A7 -> Binders | Z33: =Y33 & " (" & X33 & ")" -> Binders (Office Supplies) | AA33: ='04_product_subcategory_analysis'!E7/100 -> 0.16 | AB33: =0 -> 0
X34: ='04_product_subcategory_analysis'!B8 -> Office Supplies | Y34: ='04_product_subcategory_analysis'!A8 -> Art | Z34: =Y34 & " (" & X34 & ")" -> Art (Office Supplies) | AA34: ='04_product_subcategory_analysis'!E8/100 -> 0.16 | AB34: =0 -> 0
X35: ='04_product_subcategory_analysis'!B4 -> Office Supplies | Y35: ='04_product_subcategory_analysis'!A4 -> Envelopes | Z35: =Y35 & " (" & X35 & ")" -> Envelopes (Office Supplies) | AA35: ='04_product_subcategory_analysis'!E4/100 -> 0.17 | AB35: =0 -> 0
X36: ='04_product_subcategory_analysis'!B5 -> Technology | Y36: ='04_product_subcategory_analysis'!A5 -> Copiers | Z36: =Y36 & " (" & X36 & ")" -> Copiers (Technology) | AA36: ='04_product_subcategory_analysis'!E5/100 -> 0.17 | AB36: =0 -> 0
X37: ='04_product_subcategory_analysis'!B6 -> Technology | Y37: ='04_product_subcategory_analysis'!A6 -> Accessories | Z37: =Y37 & " (" & X37 & ")" -> Accessories (Technology) | AA37: ='04_product_subcategory_analysis'!E6/100 -> 0.17 | AB37: =0 -> 0
X38: ='04_product_subcategory_analysis'!B3 -> Office Supplies | Y38: ='04_product_subcategory_analysis'!A3 -> Labels | Z38: =Y38 & " (" & X38 & ")" -> Labels (Office Supplies) | AA38: ='04_product_subcategory_analysis'!E3/100 -> 0.2 | AB38: =0 -> 0
X39: ='04_product_subcategory_analysis'!B2 -> Office Supplies | Y39: ='04_product_subcategory_analysis'!A2 -> Paper | Z39: =Y39 & " (" & X39 & ")" -> Paper (Office Supplies) | AA39: ='04_product_subcategory_analysis'!E2/100 -> 0.24 | AB39: =0 -> 0
X41: Regional Performance
X43: Region | Y43: Revenue | Z43: OC Margin %
X44: ='05_regional_analysis'!A2 -> Central | Y44: ='05_regional_analysis'!B2 -> 2822302.5 | Z44: ='05_regional_analysis'!D2/100 -> 0.11
X45: ='05_regional_analysis'!A3 -> South | Y45: ='05_regional_analysis'!B3 -> 1600907 | Z45: ='05_regional_analysis'!D3/100 -> 0.09
B46: Tables Is the Sole Loss-Making Sub-Category at -8% Margin | M46: Revenue Concentrated in Key Regions - Margin Varies Significantly | X46: ='05_regional_analysis'!A4 -> North | Y46: ='05_regional_analysis'!B4 -> 1248165.6 | Z46: ='05_regional_analysis'!D4/100 -> 0.16
X47: ='05_regional_analysis'!A5 -> Oceania | Y47: ='05_regional_analysis'!B5 -> 1100184.6 | Z47: ='05_regional_analysis'!D5/100 -> 0.11
X48: ='05_regional_analysis'!A6 -> Southeast Asia | Y48: ='05_regional_analysis'!B6 -> 884423.17 | Z48: ='05_regional_analysis'!D6/100 -> 0.02
X49: ='05_regional_analysis'!A7 -> North Asia | Y49: ='05_regional_analysis'!B7 -> 848309.78 | Z49: ='05_regional_analysis'!D7/100 -> 0.2
...

Sheet Dashboard 2
B1: Commercial Performance Revenue - Due Dilligence Case Study | P&L
B3: Global Superstore Dataset 2011-2014 | X3: Data: Revenue and Margin Trend
AA5: 2011A | AB5: 2012A | AC5: 2013A | AD5: 2014A
X6: Furniture | AA6: ='10_analysis_time_series_categor'!C2 -> 756192.38 | AB6: ='10_analysis_time_series_categor'!C5 -> 858902.56 | AC6: ='10_analysis_time_series_categor'!C8 -> 1117723.6 | AD6: ='10_analysis_time_series_categor'!C11 -> 1378055.7
X7: Office Supplies | AA7: ='10_analysis_time_series_categor'!C3 -> 675606.45 | AB7: ='10_analysis_time_series_categor'!C6 -> 795094.63 | AC7: ='10_analysis_time_series_categor'!C9 -> 1010717.6 | AD7: ='10_analysis_time_series_categor'!C12 -> 1305651.5
X8: Technology | AA8: ='10_analysis_time_series_categor'!C4 -> 827652.06 | AB8: ='10_analysis_time_series_categor'!C7 -> 1023441.5 | AC8: ='10_analysis_time_series_categor'!C10 -> 1277305.2 | AD8: ='10_analysis_time_series_categor'!C13 -> 1616158.7
X9: Total Revenue | AA9: =SUM(AA6:AA8) -> 2259450.9 | AB9: =SUM(AB6:AB8) -> 2677438.7 | AC9: =SUM(AC6:AC8) -> 3405746.4 | AD9: =SUM(AD6:AD8) -> 4299865.9
X11: OC Margin % | AA11: ='P&L'!K14 -> 0.1102 | AB11: ='P&L'!L14 -> 0.1148 | AC11: ='P&L'!M14 -> 0.1195 | AD11: ='P&L'!N14 -> 0.1173
X13: Profit Contribution vs Revenue Share
AA15: Revenue Share % | AB15: Profit Contribution %
X16: Furniture | AA16: ='03_cateogry_analysis'!E3/100 -> 0.3252 | AB16: ='07_profit_analysis'!F4/100 -> 0.1944
X17: Office Supplies | AA17: ='03_cateogry_analysis'!E4/100 -> 0.2996 | AB17: ='07_profit_analysis'!F3/100 -> 0.3533
X18: Technology | AA18: ='03_cateogry_analysis'!E2/100 -> 0.3753 | AB18: ='07_profit_analysis'!F2/100 -> 0.4523
B20: Revenue Growing at 24% CAGR - Margin Stable at 12% | M20: Office Supplies Significantly Under-Contributing to Profit | X20: Sub-Category Margin Ranked
X22: Category | Y22: Subcategory | Z22: Axis Title | AA22: Margin % | AB22: Zero Line
X23: ='04_product_subcategory_analysis'!B18 -> Furniture | Y23: ='04_product_subcategory_analysis'!A18 -> Tables | Z23: =Y23 & " (" & X23 & ")" -> Tables (Furniture) | AA23: ='04_product_subcategory_analysis'!E18/100 -> -0.08 | AB23: =0 -> 0
X24: ='04_product_subcategory_analysis'!B17 -> Technology | Y24: ='04_product_subcategory_analysis'!A17 -> Machines | Z24: =Y24 & " (" & X24 & ")" -> Machines (Technology) | AA24: ='04_product_subcategory_analysis'!E17/100 -> 0.08 | AB24: =0 -> 0
X25: ='04_product_subcategory_analysis'!B15 -> Office Supplies | Y25: ='04_product_subcategory_analysis'!A15 -> Supplies | Z25: =Y25 & " (" & X25 & ")" -> Supplies (Office Supplies) | AA25: ='04_product_subcategory_analysis'!E15/100 -> 0.09 | AB25: =0 -> 0
X26: ='04_product_subcategory_analysis'!B16 -> Furniture | Y26: ='04_product_subcategory_analysis'!A16 -> Chairs | Z26: =Y26 & " (" & X26 & ")" -> Chairs (Furniture) | AA26: ='04_product_subcategory_analysis'!E16/100 -> 0.09 | AB26: =0 -> 0
X27: ='04_product_subcategory_analysis'!B14 -> Office Supplies | Y27: ='04_product_subcategory_analysis'!A14 -> Storage | Z27: =Y27 & " (" & X27 & ")" -> Storage (Office Supplies) | AA27: ='04_product_subcategory_analysis'!E14/100 -> 0.1 | AB27: =0 -> 0
X28: ='04_product_subcategory_analysis'!B13 -> Furniture | Y28: ='04_product_subcategory_analysis'!A13 -> Bookcases | Z28: =Y28 & " (" & X28 & ")" -> Bookcases (Furniture) | AA28: ='04_product_subcategory_analysis'!E13/100 -> 0.11 | AB28: =0 -> 0
X29: ='04_product_subcategory_analysis'!B12 -> Furniture | Y29: ='04_product_subcategory_analysis'!A12 -> Furnishings | Z29: =Y29 & " (" & X29 & ")" -> Furnishings (Furniture) | AA29: ='04_product_subcategory_analysis'!E12/100 -> 0.12 | AB29: =0 -> 0
X30: ='04_product_subcategory_analysis'!B11 -> Technology | Y30: ='04_product_subcategory_analysis'!A11 -> Phones | Z30: =Y30 & " (" & X30 & ")" -> Phones (Technology) | AA30: ='04_product_subcategory_analysis'!E11/100 -> 0.13 | AB30: =0 -> 0
X31: ='04_product_subcategory_analysis'!B9 -> Office Supplies | Y31: ='04_product_subcategory_analysis'!A9 -> Fasteners | Z31: =Y31 & " (" & X31 & ")" -> Fasteners (Office Supplies) | AA31: ='04_product_subcategory_analysis'!E9/100 -> 0.14 | AB31: =0 -> 0
X32: ='04_product_subcategory_analysis'!B10 -> Office Supplies | Y32: ='04_product_subcategory_analysis'!A10 -> Appliances | Z32: =Y32 & " (" & X32 & ")" -> Appliances (Office Supplies) | AA32: ='04_product_subcategory_analysis'!E10/100 -> 0.14 | AB32: =0 -> 0
X33: ='04_product_subcategory_analysis'!B7 -> Office Supplies | Y33: ='04_product_subcategory_analysis'!A7 -> Binders | Z33: =Y33 & " (" & X33 & ")" -> Binders (Office Supplies) | AA33: ='04_product_subcategory_analysis'!E7/100 -> 0.16 | AB33: =0 -> 0
X34: ='04_product_subcategory_analysis'!B8 -> Office Supplies | Y34: ='04_product_subcategory_analysis'!A8 -> Art | Z34: =Y34 & " (" & X34 & ")" -> Art (Office Supplies) | AA34: ='04_product_subcategory_analysis'!E8/100 -> 0.16 | AB34: =0 -> 0
X35: ='04_product_subcategory_analysis'!B4 -> Office Supplies | Y35: ='04_product_subcategory_analysis'!A4 -> Envelopes | Z35: =Y35 & " (" & X35 & ")" -> Envelopes (Office Supplies) | AA35: ='04_product_subcategory_analysis'!E4/100 -> 0.17 | AB35: =0 -> 0
X36: ='04_product_subcategory_analysis'!B5 -> Technology | Y36: ='04_product_subcategory_analysis'!A5 -> Copiers | Z36: =Y36 & " (" & X36 & ")" -> Copiers (Technology) | AA36: ='04_product_subcategory_analysis'!E5/100 -> 0.17 | AB36: =0 -> 0
X37: ='04_product_subcategory_analysis'!B6 -> Technology | Y37: ='04_product_subcategory_analysis'!A6 -> Accessories | Z37: =Y37 & " (" & X37 & ")" -> Accessories (Technology) | AA37: ='04_product_subcategory_analysis'!E6/100 -> 0.17 | AB37: =0 -> 0
X38: ='04_product_subcategory_analysis'!B3 -> Office Supplies | Y38: ='04_product_subcategory_analysis'!A3 -> Labels | Z38: =Y38 & " (" & X38 & ")" -> Labels (Office Supplies) | AA38: ='04_product_subcategory_analysis'!E3/100 -> 0.2 | AB38: =0 -> 0
X39: ='04_product_subcategory_analysis'!B2 -> Office Supplies | Y39: ='04_product_subcategory_analysis'!A2 -> Paper | Z39: =Y39 & " (" & X39 & ")" -> Paper (Office Supplies) | AA39: ='04_product_subcategory_analysis'!E2/100 -> 0.24 | AB39: =0 -> 0
X41: Regional Performance
X43: Region | Y43: Revenue | Z43: OC Margin %
X44: ='05_regional_analysis'!A2 -> Central | Y44: ='05_regional_analysis'!B2 -> 2822302.5 | Z44: ='05_regional_analysis'!D2/100 -> 0.11
X45: ='05_regional_analysis'!A3 -> South | Y45: ='05_regional_analysis'!B3 -> 1600907 | Z45: ='05_regional_analysis'!D3/100 -> 0.09
B46: Tables Is the Sole Loss-Making Sub-Category at -8% Margin | M46: Revenue Concentrated in Key Regions - Margin Varies Significantly | X46: ='05_regional_analysis'!A4 -> North | Y46: ='05_regional_analysis'!B4 -> 1248165.6 | Z46: ='05_regional_analysis'!D4/100 -> 0.16
X47: ='05_regional_analysis'!A5 -> Oceania | Y47: ='05_regional_analysis'!B5 -> 1100184.6 | Z47: ='05_regional_analysis'!D5/100 -> 0.11
X48: ='05_regional_analysis'!A6 -> Southeast Asia | Y48: ='05_regional_analysis'!B6 -> 884423.17 | Z48: ='05_regional_analysis'!D6/100 -> 0.02
X49: ='05_regional_analysis'!A7 -> North Asia | Y49: ='05_regional_analysis'!B7 -> 848309.78 | Z49: ='05_regional_analysis'!D7/100 -> 0.2
...

Sheet 09_unit_economics_diagnostic
A1: Sub-Category | B1: Category | C1: total_revenue | D1: total_profit | E1: profit_margin | F1: discount | G1: average_selling_price | H1: average_unit_cost | I1: average_unit_profit | J1: commerical_risk_flag
A2: Tables | B2: Furniture | C2: 757041.92 | D2: -64083.39 | E2: -8.46 | F2: 0.29 | G2: 245.55 | H2: 266.34 | I2: -20.79 | J2: Pricing Risk-Excessive Discounting
A3: Machines | B3: Technology | C3: 779060.07 | D3: 58867.87 | E3: 7.56 | F3: 0.17 | G3: 158.8 | H3: 146.8 | I3: 12 | J3: Acceptable
A4: Supplies | B4: Office Supplies | C4: 243074.22 | D4: 22583.26 | E4: 9.29 | F4: 0.13 | G4: 28.45 | H4: 25.81 | I4: 2.64 | J4: Acceptable
A5: Chairs | B5: Furniture | C5: 1501681.8 | D5: 140396.27 | E5: 9.35 | F5: 0.16 | G5: 121.73 | H5: 110.35 | I5: 11.38 | J5: Acceptable
A6: Storage | B6: Office Supplies | C6: 1127085.9 | D6: 108461.49 | E6: 9.62 | F6: 0.14 | G6: 66.62 | H6: 60.21 | I6: 6.41 | J6: Acceptable
A7: Bookcases | B7: Furniture | C7: 1466572.2 | D7: 161924.42 | E7: 11.04 | F7: 0.15 | G7: 176.48 | H7: 157 | I7: 19.49 | J7: Acceptable
A8: Furnishings | B8: Furniture | C8: 385578.26 | D8: 46967.43 | E8: 12.18 | F8: 0.15 | G8: 34.35 | H8: 30.17 | I8: 4.18 | J8: Acceptable
A9: Phones | B9: Technology | C9: 1706824.1 | D9: 216717.01 | E9: 12.7 | F9: 0.15 | G9: 143.79 | H9: 125.54 | I9: 18.26 | J9: Acceptable
A10: Fasteners | B10: Office Supplies | C10: 83242.32 | D10: 11525.42 | E10: 13.85 | F10: 0.14 | G10: 9.92 | H10: 8.55 | I10: 1.37 | J10: Acceptable
A11: Appliances | B11: Office Supplies | C11: 1011064.3 | D11: 141680.59 | E11: 14.01 | F11: 0.14 | G11: 166.35 | H11: 143.04 | I11: 23.31 | J11: Acceptable
A12: Art | B12: Office Supplies | C12: 372091.97 | D12: 57953.91 | E12: 15.58 | F12: 0.12 | G12: 22.83 | H12: 19.27 | I12: 3.56 | J12: Acceptable
A13: Binders | B13: Office Supplies | C13: 461911.51 | D13: 72449.85 | E13: 15.68 | F13: 0.18 | G13: 21.56 | H13: 18.17 | I13: 3.38 | J13: Acceptable
... A18: Paper | B18: Office Supplies | C18: 244291.72 | D18: 59207.68 | E18: 24.24 | F18: 0.11 | G18: 19.05 | H18: 14.43 | I18: 4.62 | J18: Acceptable

Sheet 08_discount
A1: Discount
A2: 0.14290755

Sheet 07_profit_analysis
A1: product_category | B1: total_revenue | C1: total_profit | D1: profit_margin | E1: revenue_share_pct | F1: profit_contribution_pct | G1: profit_vs_revenue_gap
A2: Technology | B2: 4744557.5 | C2: 663778.73 | D2: 14 | E2: 37.53 | F2: 45.23 | G2: 7.7
A3: Office Supplies | B3: 3787070.2 | C3: 518473.83 | D3: 14 | E3: 29.96 | F3: 35.33 | G3: 5.37
A4: Furniture | B4: 4110874.2 | C4: 285204.72 | D4: 7 | E4: 32.52 | F4: 19.44 | G4: -13.08

Sheet 06_customer_segment_analysis
A1: customer_segment | B1: total_revenue | C1: total_profit | D1: profit_margin | E1: customer_segment_revenue_contribution_pct
A2: Consumer | B2: 6507949.4 | C2: 749239.78 | D2: 12 | E2: 51.48
A3: Corporate | B3: 3824697.5 | C3: 441208.33 | D3: 12 | E3: 30.25
A4: Home Office | B4: 2309855 | C4: 277009.18 | D4: 12 | E4: 18.27

Sheet 05_regional_analysis
A1: Region | B1: total_revenue | C1: total_profit | D1: profit_margin | E1: region_revenue_contribution_pct
A2: Central | B2: 2822302.5 | C2: 311403.98 | D2: 11 | E2: 22.32
A3: South | B3: 1600907 | C3: 140355.77 | D3: 9 | E3: 12.66
A4: North | B4: 1248165.6 | C4: 194597.95 | D4: 16 | E4: 9.87
A5: Oceania | B5: 1100184.6 | C5: 120089.11 | D5: 11 | E5: 8.7
A6: Southeast Asia | B6: 884423.17 | C6: 17852.33 | D6: 2 | E6: 7
A7: North Asia | B7: 848309.78 | C7: 165578.42 | D7: 20 | E7: 6.71
A8: EMEA | B8: 806161.31 | C8: 43897.97 | D8: 5 | E8: 6.38
A9: Africa | B9: 783773.21 | C9: 88871.63 | D9: 11 | E9: 6.2
A10: Central Asia | B10: 752826.57 | C10: 132480.19 | D10: 18 | E10: 5.95
A11: West | B11: 725457.82 | C11: 108418.45 | D11: 15 | E11: 5.74
A12: East | B12: 678781.24 | C12: 91522.78 | D12: 13 | E12: 5.37
A13: Caribbean | B13: 324280.86 | C13: 34571.32 | D13: 11 | E13: 2.57
A14: Canada | B14: 66928.17 | C14: 17817.39 | D14: 27 | E14: 0.53

Sheet 04_product_subcategory_analysis
A1: Sub-Category | B1: Category | C1: total_revenue | D1: total_profit | E1: profit_margin | F1: product_subcategory_contribution_pct
A2: Paper | B2: Office Supplies | C2: 244291.72 | D2: 59207.68 | E2: 24 | F2: 1.93
A3: Labels | B3: Office Supplies | C3: 73404.03 | D3: 15010.51 | E3: 20 | F3: 0.58
A4: Envelopes | B4: Office Supplies | C4: 170904.3 | D4: 29601.12 | E4: 17 | F4: 1.35
A5: Copiers | B5: Technology | C5: 1509436.3 | D5: 258567.55 | E5: 17 | F5: 11.94
A6: Accessories | B6: Technology | C6: 749237.02 | D6: 129626.31 | E6: 17 | F6: 5.93
A7: Binders | B7: Office Supplies | C7: 461911.51 | D7: 72449.85 | E7: 16 | F7: 3.65
A8: Art | B8: Office Supplies | C8: 372091.97 | D8: 57953.91 | E8: 16 | F8: 2.94
A9: Fasteners | B9: Office Supplies | C9: 83242.32 | D9: 11525.42 | E9: 14 | F9: 0.66
A10: Appliances | B10: Office Supplies | C10: 1011064.3 | D10: 141680.59 | E10: 14 | F10: 8
A11: Phones | B11: Technology | C11: 1706824.1 | D11: 216717.01 | E11: 13 | F11: 13.5
A12: Furnishings | B12: Furniture | C12: 385578.26 | D12: 46967.43 | E12: 12 | F12: 3.05
A13: Bookcases | B13: Furniture | C13: 1466572.2 | D13: 161924.42 | E13: 11 | F13: 11.6
... A18: Tables | B18: Furniture | C18: 757041.92 | D18: -64083.39 | E18: -8 | F18: 5.99

Sheet 03_cateogry_analysis
A1: Category | B1: total_revenue | C1: total_profit | D1: profit_margin | E1: product_category_contribution_pct
A2: Technology | B2: 4744557.5 | C2: 663778.73 | D2: 14 | E2: 37.53
A3: Furniture | B3: 4110874.2 | C3: 285204.72 | D3: 7 | E3: 32.52
A4: Office Supplies | B4: 3787070.2 | C4: 518473.83 | D4: 14 | E4: 29.96

Sheet 02_analysis_time_series
A1: year | B1: total_revenue | C1: total_profit | D1: profit_margin | E1: previous_year_revenue | F1: revenue_change_pct | G1: profit_change_pct
A2: 2011 | B2: 2259450.9 | C2: 248940.81 | D2: 11.02
A3: 2012 | B3: 2677438.7 | C3: 307415.28 | D3: 11.48 | E3: 2259450.9 | F3: 18 | G3: 23
A4: 2013 | B4: 3405746.5 | C4: 406935.23 | D4: 11.95 | E4: 2677438.7 | F4: 27 | G4: 32
A5: 2014 | B5: 4299865.9 | C5: 504165.97 | D5: 11.73 | E5: 3405746.5 | F5: 26 | G5: 24

Sheet 10_analysis_time_series_categor
A1: year | B1: category | C1: total_revenue
A2: 2011 | B2: Furniture | C2: 756192.38
A3: 2011 | B3: Office Supplies | C3: 675606.45
A4: 2011 | B4: Technology | C4: 827652.06
A5: 2012 | B5: Furniture | C5: 858902.56
A6: 2012 | B6: Office Supplies | C6: 795094.63
A7: 2012 | B7: Technology | C7: 1023441.5
A8: 2013 | B8: Furniture | C8: 1117723.6
A9: 2013 | B9: Office Supplies | C9: 1010717.6
A10: 2013 | B10: Technology | C10: 1277305.2
A11: 2014 | B11: Furniture | C11: 1378055.7
A12: 2014 | B12: Office Supplies | C12: 1305651.5
A13: 2014 | B13: Technology | C13: 1616158.7

Sheet 01_data_validation
A1: Row ID | B1: Order ID | C1: Order Date | D1: Ship Date | E1: Ship Mode | F1: Customer ID | G1: Customer Name | H1: Segment | I1: City | J1: State | K1: Country | L1: Postal Code | M1: Market | N1: Region | O1: Product ID | P1: Category | Q1: Sub-Category | R1: Product Name | S1: Sales | T1: Quantity | U1: Discount | V1: Profit | W1: Shipping Cost | X1: Order Priority
A2: 32298 | B2: CA-2012-124891 | C2: 31-07-2012 | D2: 31-07-2012 | E2: Same Day | F2: RH-19495 | G2: Rick Hansen | H2: Consumer | I2: New York City | J2: New York | K2: United States | L2: 10024 | M2: US | N2: East | O2: TEC-AC-10003033 | P2: Technology | Q2: Accessories | R2: Plantronics CS510 - Over-the-Head monaural Wireless Headset System | S2: 2309.65 | T2: 7 | U2: 0 | V2: 762.1845 | W2: 933.57 | X2: Critical
A3: 26341 | B3: IN-2013-77878 | C3: 05-02-2013 | D3: 07-02-2013 | E3: Second Class | F3: JR-16210 | G3: Justin Ritter | H3: Corporate | I3: Wollongong | J3: New South Wales | K3: Australia | M3: APAC | N3: Oceania | O3: FUR-CH-10003950 | P3: Furniture | Q3: Chairs | R3: Novimex Executive Leather Armchair, Black | S3: 3709.395 | T3: 9 | U3: 0.1 | V3: -288.765 | W3: 923.63 | X3: Critical
A4: 25330 | B4: IN-2013-71249 | C4: 17-10-2013 | D4: 18-10-2013 | E4: First Class | F4: CR-12730 | G4: Craig Reiter | H4: Consumer | I4: Brisbane | J4: Queensland | K4: Australia | M4: APAC | N4: Oceania | O4: TEC-PH-10004664 | P4: Technology | Q4: Phones | R4: Nokia Smart Phone, with Caller ID | S4: 5175.171 | T4: 9 | U4: 0.1 | V4: 919.971 | W4: 915.49 | X4: Medium
A5: 13524 | B5: ES-2013-1579342 | C5: 28-01-2013 | D5: 30-01-2013 | E5: First Class | F5: KM-16375 | G5: Katherine Murray | H5: Home Office | I5: Berlin | J5: Berlin | K5: Germany | M5: EU | N5: Central | O5: TEC-PH-10004583 | P5: Technology | Q5: Phones | R5: Motorola Smart Phone, Cordless | S5: 2892.51 | T5: 5 | U5: 0.1 | V5: -96.54 | W5: 910.16 | X5: Medium
A6: 47221 | B6: SG-2013-4320 | C6: 05-11-2013 | D6: 06-11-2013 | E6: Same Day | F6: RH-9495 | G6: Rick Hansen | H6: Consumer | I6: Dakar | J6: Dakar | K6: Senegal | M6: Africa | N6: Africa | O6: TEC-SHA-10000501 | P6: Technology | Q6: Copiers | R6: Sharp Wireless Fax, High-Speed | S6: 2832.96 | T6: 8 | U6: 0 | V6: 311.52 | W6: 903.04 | X6: Critical
A7: 22732 | B7: IN-2013-42360 | C7: 28-06-2013 | D7: 01-07-2013 | E7: Second Class | F7: JM-15655 | G7: Jim Mitchum | H7: Corporate | I7: Sydney | J7: New South Wales | K7: Australia | M7: APAC | N7: Oceania | O7: TEC-PH-10000030 | P7: Technology | Q7: Phones | R7: Samsung Smart Phone, with Caller ID | S7: 2862.675 | T7: 5 | U7: 0.1 | V7: 763.275 | W7: 897.35 | X7: Critical
A8: 30570 | B8: IN-2011-81826 | C8: 07-11-2011 | D8: 09-11-2011 | E8: First Class | F8: TS-21340 | G8: Toby Swindell | H8: Consumer | I8: Porirua | J8: Wellington | K8: New Zealand | M8: APAC | N8: Oceania | O8: FUR-CH-10004050 | P8: Furniture | Q8: Chairs | R8: Novimex Executive Leather Armchair, Adjustable | S8: 1822.08 | T8: 4 | U8: 0 | V8: 564.84 | W8: 894.77 | X8: Critical
A9: 31192 | B9: IN-2012-86369 | C9: 14-04-2012 | D9: 18-04-2012 | E9: Standard Class | F9: MB-18085 | G9: Mick Brown | H9: Consumer | I9: Hamilton | J9: Waikato | K9: New Zealand | M9: APAC | N9: Oceania | O9: FUR-TA-10002958 | P9: Furniture | Q9: Tables | R9: Chromcraft Conference Table, Fully Assembled | S9: 5244.84 | T9: 6 | U9: 0 | V9: 996.48 | W9: 878.38 | X9: High
A10: 40155 | B10: CA-2014-135909 | C10: 14-10-2014 | D10: 21-10-2014 | E10: Standard Class | F10: JW-15220 | G10: Jane Waco | H10: Corporate | I10: Sacramento | J10: California | K10: United States | L10: 95823 | M10: US | N10: West | O10: OFF-BI-10003527 | P10: Office Supplies | Q10: Binders | R10: Fellowes PB500 Electric Punch Plastic Comb Binding Machine with Manual Bind | S10: 5083.96 | T10: 5 | U10: 0.2 | V10: 1906.485 | W10: 867.69 | X10: Low
A11: 40936 | B11: CA-2012-116638 | C11: 28-01-2012 | D11: 31-01-2012 | E11: Second Class | F11: JH-15985 | G11: Joseph Holt | H11: Consumer | I11: Concord | J11: North Carolina | K11: United States | L11: 28027 | M11: US | N11: South | O11: FUR-TA-10000198 | P11: Furniture | Q11: Tables | R11: Chromcraft Bull-Nose Wood Oval Conference Tables & Bases | S11: 4297.644 | T11: 13 | U11: 0.4 | V11: -1862.3124 | W11: 865.74 | X11: Critical

Sheet processed
A1: product_category | B1: total_revenue | C1: total_profit | D1: profit_margin | E1: revenue_share_pct | F1: profit_contribution_pct | G1: profit_vs_revenue_gap
A2: Technology | B2: 4744557.5 | C2: 663778.73 | D2: 14 | E2: 37.53 | F2: 45.23 | G2: 7.7
A3: Office Supplies | B3: 3787070.2 | C3: 518473.83 | D3: 14 | E3: 29.96 | F3: 35.33 | G3: 5.37
A4: Furniture | B4: 4110874.2 | C4: 285204.72 | D4: 7 | E4: 32.52 | F4: 19.44 | G4: -13.08

Sheet Sheet6
D3: Commercial Performance Revuew - Due Dilligence Case Study
D5: Kenneth Christopher | April 2026
B9: Data Source | D9: Global Superstore transactional Dataset 2011-2014
B11: Key Investment Question | D11: Should an
B15: Investment View | D15: Conditional Buy
B17: The busness demonstrates strong revenue growth and stable margins, but value is unevenly distributed across categories. Profitabillity is heavily concentrated in Technology and Office Supplies, while Furniture exhibits structural underperformance. Value creation is achievable through portfolio optimisation and pricing discipline
